<?xml version ="1.0" encoding="utf-8"?>

<robot name ="smartsix">

    <link name ="base_link">
        <!-- <inertial>
        </inertial> -->
        <visual>
            <origin xyz="0 0 0" rpy="0 0 0"/>
            <geometry>
                <mesh filename="package://fanuc_description/meshes/visual/link_0.dae"/>
            </geometry>
            <material name =""/>
        </visual>
        <collision>
            <origin xyz="0 0 0" rpy="0 0 0"/>
            <geometry>
                <mesh filename="package://fanuc_description/meshes/collision/link_0.stl"/>
            </geometry>
        </collision>
    </link>

    <link name ="link1">
        <visual> 
            <origin xyz="0 0 0" rpy="0 0 0"/>
            <geometry>
                <mesh filename="package://fanuc_description/meshes/visual/link_1.dae"/>
            </geometry>
            <material name ="red"/>
        </visual>
        <collision>
            <origin xyz="0 0 0" rpy="0 0 0"/>
            <geometry>
                <mesh filename="package://fanuc_description/meshes/collision/link_1.stl"/>
            </geometry>
        </collision>
    </link>

    <link name ="link2">
        <visual> <!--0.15 0 0.525 -->
            <origin xyz="-0.15 0.525 0" rpy="1.5788 0 0"/>
            <geometry>
                <mesh filename="package://fanuc_description/meshes/visual/link_2.dae"/>
            </geometry>
            <material name ="blue"/>
        </visual>
        <collision>
            <origin xyz="-0.15 0.525 0" rpy="1.5788 0 0"/>
            <geometry>
                <mesh filename="package://fanuc_description/meshes/collision/link_2.stl"/>
            </geometry>
        </collision>
    </link>

    <link name ="link3">
        <visual>
            <origin xyz="-0.15 1.315 0" rpy="1.5788 0 0"/>
            <geometry>
                <mesh filename="package://fanuc_description/meshes/visual/link_3.dae"/>
            </geometry>
            <material name ="green"/>
        </visual>
        <collision>
            <origin xyz="-0.15 1.315 0" rpy="1.5788 0 0"/>
            <geometry>
                <mesh filename="package://fanuc_description/meshes/collision/link_3.stl"/>
            </geometry>
        </collision>
    </link>

    <link name ="link4"> <!-- 1.465 0 -0.15 -->
        <visual>
            <origin xyz="0 1.465 -0.15" rpy="1.5788 -1.5788 0"/>
            <geometry>
                <mesh filename="package://fanuc_description/meshes/visual/link_4.dae"/>
            </geometry>
            <material name =""/>
        </visual>
        <collision>
            <origin xyz="0 1.465 -0.15" rpy="1.5788 -1.5788 0"/>
            <geometry>
                <mesh filename="package://fanuc_description/meshes/collision/link_4.stl"/>
            </geometry>
        </collision>
    </link>

    <link name ="link5"> <!-- <origin xyz="1.01 1.465 -0.012" rpy="1.5788 3.1412 0"/> -->
        <visual>
            <origin xyz="-1.01 1.465 0.01" rpy="1.5788 0 0"/>
            <geometry>
                <mesh filename="package://fanuc_description/meshes/visual/link_5.dae"/>
            </geometry>
            <material name =""/>
        </visual>
        <collision>
            <origin xyz="-1.01 1.465 0.01" rpy="1.5788 0 0"/>
            <geometry>
                <mesh filename="package://fanuc_description/meshes/collision/link_5.stl"/>
            </geometry>
        </collision>
    </link>

    <link name ="link6">
        <visual>
            <origin xyz="0 0 0.1" rpy="0 0 0"/>
            <geometry>
                <mesh filename="package://fanuc_description/meshes/visual/link_6.dae"/>
            </geometry>
            <material name =""/>
        </visual>
        <collision>
            <origin xyz="0 0 0.1" rpy="0 0 0"/>
            <geometry>
                <mesh filename="package://fanuc_description/meshes/collision/link_6.stl"/>
            </geometry>
        </collision>
    </link>

    <link name ="flange"/>

    <joint name ="joint1" type="revolute">
        <parent link="base_link"/>
        <child link="link1"/>
        <origin xyz="0 0 0" rpy="0 0 0"/>
        <axis xyz="0 0 1"/>
        <limit lower="-2.967" upper="2.967" effort="12" velocity="3.4"/>
    </joint>

    <joint name ="joint2" type="revolute">
        <parent link="link1"/>
        <child link="link2"/>
        <origin xyz="0.15 0 0.525" rpy="-1.5788 0 0"/>
        <axis xyz="0 0 1"/>
        <limit lower="-2.27" upper="2.27" effort="12" velocity="3.05"/>
    </joint>

    <joint name ="joint3" type="revolute">
        <parent link="link2"/>
        <child link="link3"/>
        <origin xyz="0 -0.790 0" rpy="0 0 0"/>
        <axis xyz="0 0 1"/>
        <limit lower="-4" upper="4" effort="12" velocity="3.14"/>
    </joint>

    <joint name ="joint4" type="revolute">
        <parent link="link3"/>
        <child link="link4"/>
        <origin xyz="0 -0.15 0" rpy="0 1.5788 0"/>
        <axis xyz="0 0 1"/>
        <limit lower="-3.49" upper="3.49" effort="45.1" velocity="7.07"/>
    </joint>

    <joint name ="joint5" type="revolute">
        <parent link="link4"/>
        <child link="link5"/>
        <origin xyz="0 0 0.860" rpy="0 -1.5788 0"/>
        <axis xyz="0 0 1"/>
        <limit lower="-2.445" upper="2.445" effort="45.1" velocity="7.07"/>
    </joint>

    <joint name ="joint6" type="revolute">
        <parent link="link5"/>
        <child link="link6"/>
        <origin xyz="0 0 0" rpy=" 0 1.5788 0"/>
        <axis xyz="0 0 1"/>
        <limit lower="-7.855" upper="7.855" effort="30" velocity="10.73"/>
    </joint> 

    <joint name ="flange" type="fixed">
        <parent link="link6"/>
        <child link="flange"/>
        <origin xyz="0 0 0.1" rpy="0 0 0"/>
    </joint>

</robot>